{"name": "test_getting_users_list", "status": "broken", "statusDetails": {"message": "pydantic.error_wrappers.ValidationError: 1 validation error for User\nname\n  value is not a valid integer (type=type_error.integer)", "trace": "get_users = <Response [200]>, make_number = 966\n\n    def test_getting_users_list(get_users, make_number):\n>       Response(get_users).asser_status_code(200).validate(User)\n\ntests/users/test_users.py:10: \n_ _ _ _ _ _ _ _ _ _ _ _ _ _ _ _ _ _ _ _ _ _ _ _ _ _ _ _ _ _ _ _ _ _ _ _ _ _ _ _ _ _ _ _ _ _ _ _ _ _ _ _ _ _ _ _ _ _ _ _ _ _ _ _ _ _ _ _ _ _ _ _ _ _ _ _ _ _ _ _ _ _ _ _ _ _ _ _ _ _ _ _ _ _ _ _ _ _ _ _ _ _ _ _ _ _ _ _ _ _ _ _\nsrc/baseclasses/response.py:15: in validate\n    schema.parse_obj(item)\npydantic/main.py:521: in pydantic.main.BaseModel.parse_obj\n    ???\n_ _ _ _ _ _ _ _ _ _ _ _ _ _ _ _ _ _ _ _ _ _ _ _ _ _ _ _ _ _ _ _ _ _ _ _ _ _ _ _ _ _ _ _ _ _ _ _ _ _ _ _ _ _ _ _ _ _ _ _ _ _ _ _ _ _ _ _ _ _ _ _ _ _ _ _ _ _ _ _ _ _ _ _ _ _ _ _ _ _ _ _ _ _ _ _ _ _ _ _ _ _ _ _ _ _ _ _ _ _ _ _\n\n>   ???\nE   pydantic.error_wrappers.ValidationError: 1 validation error for User\nE   name\nE     value is not a valid integer (type=type_error.integer)\n\npydantic/main.py:341: ValidationError"}, "attachments": [{"name": "stdout", "source": "96badb60-05a8-4c2a-99c5-5d368210de9b-attachment.txt", "type": "text/plain"}], "start": 1659756043927, "stop": 1659756043928, "uuid": "83eb7a34-e036-47e0-bd07-293c04e2fcda", "historyId": "a8cd091c167665d3ed0d6c85ad20edfc", "testCaseId": "f3a35b35911a2442325e664a2ed974e0", "fullName": "tests.users.test_users#test_getting_users_list", "labels": [{"name": "parentSuite", "value": "tests.users"}, {"name": "suite", "value": "test_users"}, {"name": "host", "value": "ivan-pc"}, {"name": "thread", "value": "7628-MainThread"}, {"name": "framework", "value": "pytest"}, {"name": "language", "value": "cpython3"}, {"name": "package", "value": "tests.users.test_users"}]}